<?xml version="1.0" encoding="utf-8"?>
<robot name="arm" xmlns:xacro="http://ros.org/wiki/xacro">
  <xacro:property name="M_PI"   value="3.1415926535897931"/>

  <link
    name="link1">
    <inertial>
      <origin
        xyz="9.55287669839149E-05 0.000953445773182543 0.0181622223429797"
        rpy="0 0 0" />
      <mass
        value="0.018996290781889" />
      <inertia
        ixx="3.52401713486466E-06"
        ixy="-9.57766622211234E-11"
        ixz="1.77834467690429E-11"
        iyy="2.92480468671507E-06"
        iyz="2.27263787135776E-08"
        izz="2.43231516201483E-06" />
    </inertial>
    <visual>
      <origin
        xyz="0 0 0"
        rpy="0 0 0" />
      <geometry>
        <mesh
          filename="package://jetrover_description/meshes/arm/link1.STL" />
      </geometry>
      <material name="green"/>
    </visual>
    <collision>
      <origin
        xyz="0 0 0"
        rpy="0 0 0" />
      <geometry>
        <mesh
          filename="package://jetrover_description/meshes/arm/link1.STL" />
      </geometry>
    </collision>
  </link>

  <link
    name="servo_link1">
    <inertial>
      <origin
        xyz="6.74971199241745E-05 -0.00653404855626152 0.0238958340366914"
        rpy="0 0 0" />
      <mass
        value="0.0116330609777772" />
      <inertia
        ixx="1.75977694435981E-06"
        ixy="-9.73060826949638E-11"
        ixz="2.47639220332551E-12"
        iyy="2.04910641988494E-06"
        iyz="-1.98639869902586E-08"
        izz="5.57260556249774E-07" />
    </inertial>
    <visual>
      <origin
        xyz="0 0 0"
        rpy="0 0 0" />
      <geometry>
        <mesh
          filename="package://jetrover_description/meshes/arm/servo_link1.STL" />
      </geometry>
      <material name="black"/>
    </visual>
    <collision>
      <origin
        xyz="0 0 0"
        rpy="0 0 0" />
      <geometry>
        <mesh
          filename="package://jetrover_description/meshes/arm/servo_link1_collision.stl" />
      </geometry>
    </collision>
  </link>
  <joint
    name="servo_joint1"
    type="fixed">
    <origin
      xyz="0 0 0"
      rpy="0 0 0" />
    <parent
      link="link1" />
    <child
      link="servo_link1" />
    <axis
      xyz="0 0 0" />
  </joint>
  <link
    name="link2">
    <inertial>
      <origin
        xyz="0.000156299570425157 -0.000455113699913916 0.0717727028511975"
        rpy="0 0 0" />
      <mass
        value="0.0329250074531705" />
      <inertia
        ixx="3.91620966174037E-05"
        ixy="-5.45461883923424E-11"
        ixz="-1.84994427464167E-07"
        iyy="3.08453562297899E-05"
        iyz="3.5881427402197E-09"
        izz="1.15081900975983E-05" />
    </inertial>
    <visual>
      <origin
        xyz="0 0 0"
        rpy="0 0 0" />
      <geometry>
        <mesh
          filename="package://jetrover_description/meshes/arm/link2.STL" />
      </geometry>
      <material name="green"/>
    </visual>
    <collision>
      <origin
        xyz="0 0 0"
        rpy="0 0 0" />
      <geometry>
        <mesh
          filename="package://jetrover_description/meshes/arm/link2_collision.stl" />
      </geometry>
    </collision>
  </link>
  <joint
    name="joint2"
    type="revolute">
    <origin
      xyz="0 0 0.0338648012164686"
      rpy="0 0 0" />
    <parent
      link="servo_link1" />
    <child
      link="link2" />
    <axis
      xyz="0 1 0" />
    <limit
      lower="-2.09"
      upper="2.09"
      effort="1000"
      velocity="10" />
  </joint>
  <link
    name="link3">
    <inertial>
      <origin
        xyz="0.000128456440925698 -0.000761424622733717 0.071772743785429"
        rpy="0 0 0" />
      <mass
        value="0.0329250074463074" />
      <inertia
        ixx="3.91621699579612E-05"
        ixy="-5.40097530558062E-11"
        ixz="-1.73786652512013E-07"
        iyy="3.08451969920239E-05"
        iyz="3.63874236522223E-09"
        izz="1.15078234912494E-05" />
    </inertial>
    <visual>
      <origin
        xyz="0 0 0"
        rpy="0 0 0" />
      <geometry>
        <mesh
          filename="package://jetrover_description/meshes/arm/link3.STL" />
      </geometry>
      <material name="green"/>
    </visual>
    <collision>
      <origin
        xyz="0 0 0"
        rpy="0 0 0" />
      <geometry>
        <mesh
          filename="package://jetrover_description/meshes/arm/link3_collision.stl" />
      </geometry>
    </collision>
  </link>
  <joint
    name="joint3"
    type="revolute">
    <origin
      xyz="0 0 0.129416446394797"
      rpy="0 0 0" />
    <parent
      link="link2" />
    <child
      link="link3" />
    <axis
      xyz="0 1 0" />
    <limit
      lower="-2.09"
      upper="2.09"
      effort="1000"
      velocity="10" />
  </joint>
  <link
    name="link4">
    <inertial>
      <origin
        xyz="-0.000261855576526311 0.000239368359066633 0.0220971301535388"
        rpy="0 0 0" />
      <mass
        value="0.00959141779390409" />
      <inertia
        ixx="7.94977139591732E-06"
        ixy="-8.29446018776969E-10"
        ixz="5.6880898756802E-08"
        iyy="4.29063067361656E-06"
        iyz="-1.84622131688891E-10"
        izz="5.33833388813501E-06" />
    </inertial>
    <visual>
      <origin
        xyz="0 0 0"
        rpy="0 0 0" />
      <geometry>
        <mesh
          filename="package://jetrover_description/meshes/arm/link4.STL" />
      </geometry>
      <material name="green"/>
    </visual>
    <collision>
      <origin
        xyz="0 0 0"
        rpy="0 0 0" />
      <geometry>
        <mesh
          filename="package://jetrover_description/meshes/arm/link4_collision.stl" />
      </geometry>
    </collision>
  </link>
  <joint
    name="joint4"
    type="revolute">
    <origin
      xyz="0 0 0.129444631186569"
      rpy="0 0 0" />
    <parent
      link="link3" />
    <child
      link="link4" />
    <axis
      xyz="0 1 0" />
    <limit
      lower="-2.09"
      upper="2.09"
      effort="1000"
      velocity="10" />
  </joint>
  <link
    name="servo_link2">
    <inertial>
      <origin
        xyz="0.00829457691057159 0.000114732113040695 -0.0125525321145837"
        rpy="0 0 0" />
      <mass
        value="0.00701021225113507" />
      <inertia
        ixx="6.10646998888003E-07"
        ixy="1.66839713815154E-09"
        ixz="-2.07626862362467E-08"
        iyy="9.477990166652E-07"
        iyz="5.12927100881908E-09"
        izz="1.44691449724265E-06" />
    </inertial>
    <visual>
      <origin
        xyz="0 0 0"
        rpy="0 0 0" />
      <geometry>
        <mesh
          filename="package://jetrover_description/meshes/arm/servo_link2.STL" />
      </geometry>
      <material name="black"/>
    </visual>
    <collision>
      <origin
        xyz="0 0 0"
        rpy="0 0 0" />
      <geometry>
        <mesh
          filename="package://jetrover_description/meshes/arm/servo_link2_collision.stl" />
      </geometry>
    </collision>
  </link>
  <joint
    name="servo_joint2"
    type="fixed">
    <origin
      xyz="0 0 0.0544833339503674"
      rpy="0 0 0" />
    <parent
      link="link4" />
    <child
      link="servo_link2" />
    <axis
      xyz="0 0 0" />
  </joint>
  <link
    name="link5">
    <inertial>
      <origin
        xyz="-5.40141895711381E-05 -8.30141354428709E-06 0.00351551092860852"
        rpy="0 0 0" />
      <mass
        value="0.00101775298619909" />
      <inertia
        ixx="2.35834256739382E-08"
        ixy="-1.92177809145012E-12"
        ixz="-3.88572739181837E-12"
        iyy="2.35740360938003E-08"
        iyz="-1.1228386368903E-13"
        izz="4.40224050991292E-08" />
    </inertial>
    <visual>
      <origin
        xyz="0 0 0"
        rpy="0 0 0" />
      <geometry>
        <mesh
          filename="package://jetrover_description/meshes/arm/link5.STL" />
      </geometry>
      <material name="black"/>
    </visual>
    <collision>
      <origin
        xyz="0 0 0"
        rpy="0 0 0" />
      <geometry>
        <mesh
          filename="package://jetrover_description/meshes/arm/link5.STL" />
      </geometry>
    </collision>
  </link>
  <joint
    name="joint5"
    type="revolute">
    <origin
      xyz="0 0 0"
      rpy="0 0 0" />
    <parent
      link="servo_link2" />
    <child
      link="link5" />
    <axis
      xyz="0 0 -1" />
    <limit
      lower="-2.09"
      upper="2.09"
      effort="1000"
      velocity="10" />
  </joint>
  <link
    name="gripper_link">
    <inertial>
      <origin
        xyz="0.0145481835889059 -0.00315257290321308 0.0253492053712461"
        rpy="0 0 0" />
      <mass
        value="0.0174988490314194" />
      <inertia
        ixx="4.12615692688456E-06"
        ixy="-2.75102939068049E-08"
        ixz="-7.61180742281118E-09"
        iyy="1.57023365316943E-06"
        iyz="2.2563082379695E-08"
        izz="3.2612101868791E-06" />
    </inertial>
    <visual>
      <origin
        xyz="0 0 0"
        rpy="0 0 0" />
      <geometry>
        <mesh
          filename="package://jetrover_description/meshes/arm/gripper_link.STL" />
      </geometry>
      <material name="black"/>
    </visual>
    <collision>
      <origin
        xyz="0 0 0"
        rpy="0 0 0" />
      <geometry>
        <mesh
          filename="package://jetrover_description/meshes/arm/gripper_link_collision.stl" />
      </geometry>
    </collision>
  </link>
  <joint
    name="gripper_joint"
    type="fixed">
    <origin
      xyz="0 0 0.0054388"
      rpy="0 0 0" />
    <parent
      link="link5" />
    <child
      link="gripper_link" />
    <axis
      xyz="0 0 0" />
  </joint>

  <!-- end effector link -->
  <link name="end_effector_link" />

  <joint name="end_effector_joint" type="fixed">
    <origin xyz="0 0 0.08" rpy="0 0 0"/>
    <parent link="link5"/>
    <child link="end_effector_link"/>
  </joint>

</robot>
